Workbook

Sheet sku商品编码
A1: 组合编码 | B1: 单品编码 | C1: 商品名称 | D1: 数量 | E1: 单品成本 | F1: sku成本
A2: QWH4891035068884YWXCC | B2: QWH4891035068884YWXCC | C2: =VLOOKUP(B2,成本表!A:B,2,FALSE) -> 雅培怡保康礼盒850G*2 | D2: 1 | E2: =VLOOKUP(B2,成本表!A:C,3,FALSE) -> 382 | F2: =E2*D2 -> 382
A3: QWH8886451011299YWXCC | B3: QWH8886451011299YWXCC | C3: =VLOOKUP(B3,成本表!A:B,2,FALSE) -> 雅培怡保康850G | D3: 1 | E3: =VLOOKUP(B3,成本表!A:C,3,FALSE) -> 187 | F3: =E3*D3 -> 187
A4: QWH8886451011299YWXCC-3 | B4: QWH8886451011299YWXCC | C4: =VLOOKUP(B4,成本表!A:B,2,FALSE) -> 雅培怡保康850G | D4: 3 | E4: =VLOOKUP(B4,成本表!A:C,3,FALSE) -> 187 | F4: =E4*D4 -> 561
A5: QWH8886451011299YWXCC-6 | B5: QWH8886451011299YWXCC | C5: =VLOOKUP(B5,成本表!A:B,2,FALSE) -> 雅培怡保康850G | D5: 6 | E5: =VLOOKUP(B5,成本表!A:C,3,FALSE) -> 187 | F5: =E5*D5 -> 1122
A6: RN84745786897219091815 | B6: RN84745786897219091815 | C6: =VLOOKUP(B6,成本表!A:B,2,FALSE) -> 雅培怡保康850G | D6: 1 | E6: =VLOOKUP(B6,成本表!A:C,3,FALSE) -> 187 | F6: =E6*D6 -> 187
A7: QWH4891035069164YWXCC | B7: QWH4891035069164YWXCC | C7: =VLOOKUP(B7,成本表!A:B,2,FALSE) -> 雅培金装礼盒900G*2 | D7: 1 | E7: =VLOOKUP(B7,成本表!A:C,3,FALSE) -> 338 | F7: =E7*D7 -> 338
A8: QWH4891035065913YWXC-2 | B8: QWH4891035065913YWXC | C8: =VLOOKUP(B8,成本表!A:B,2,FALSE) -> 雅培金装900G | D8: 2 | E8: =VLOOKUP(B8,成本表!A:C,3,FALSE) -> 180 | F8: =E8*D8 -> 360
A9: QWH4891035065913YWXC-3 | B9: QWH4891035065913YWXC | C9: =VLOOKUP(B9,成本表!A:B,2,FALSE) -> 雅培金装900G | D9: 3 | E9: =VLOOKUP(B9,成本表!A:C,3,FALSE) -> 180 | F9: =E9*D9 -> 540
A10: QWH4891035065913AYWXCC | B10: QWH4891035065913AYWXCC | C10: =VLOOKUP(B10,成本表!A:B,2,FALSE) -> 雅培金装900G | D10: 1 | E10: =VLOOKUP(B10,成本表!A:C,3,FALSE) -> 180 | F10: =E10*D10 -> 180
A11: QWH4891035065982AYWXCC-2 | B11: QWH4891035065982AYWXCC | C11: =VLOOKUP(B11,成本表!A:B,2,FALSE) -> 雅培低糖850G | D11: 2 | E11: =VLOOKUP(B11,成本表!A:C,3,FALSE) -> 175 | F11: =E11*D11 -> 350
A12: QWH4891035065982AYWXCC | B12: QWH4891035065982AYWXCC | C12: =VLOOKUP(B12,成本表!A:B,2,FALSE) -> 雅培低糖850G | D12: 1 | E12: =VLOOKUP(B12,成本表!A:C,3,FALSE) -> 175 | F12: =E12*D12 -> 175
A13: QWH4891035065982YWXC | B13: QWH4891035065982YWXC | C13: =VLOOKUP(B13,成本表!A:B,2,FALSE) -> 雅培低糖850G | D13: 1 | E13: =VLOOKUP(B13,成本表!A:C,3,FALSE) -> 175 | F13: =E13*D13 -> 175
... A23: QWH043900293219YWXCZY-2 | B23: QWH043900293219YWXCZY | C23: =VLOOKUP(B23,成本表!A:B,2,FALSE) -> 雀巢蛋白补227 | D23: 2 | E23: =VLOOKUP(B23,成本表!A:C,3,FALSE) -> 72.5 | F23: =E23*D23 -> 145
A24: QWH043900293219YWXCZY-4 | B24: QWH043900293219YWXCZY | C24: 雀巢蛋白补*4 | D24: 4 | E24: 72.5 | F24: =E24*D24 -> 290
A25: QWH8445290770189YWXCZY-6 | B25: QWH8445290770189YWXCZY | C25: 雀巢代餐奶昔-巧克力味 | D25: 6 | E25: 107 | F25: =E25*D25 -> 642
A26: QWH8445290770189YWXCZY-3 | B26: QWH8445290770189YWXCZY | C26: 雀巢代餐奶昔-巧克力味 | D26: 3 | E26: 107 | F26: =E26*D26 -> 321
A27: 女银275粒 | B27: 女银275粒 | C27: 女银275粒 | D27: 1 | E27: 87 | F27: =E27*D27 -> 87
A28: 女维200粒两瓶装 | B28: 女维200粒两瓶装 | C28: 女维200粒两瓶装 | D28: 1 | E28: 130 | F28: =E28*D28 -> 130
A29: 女维200粒 | B29: 女维200粒 | C29: 女维200粒 | D29: 1 | E29: 65 | F29: =E29*D29 -> 65
A30: 男银275粒 | B30: 男银275粒 | C30: 男银275粒 | D30: 1 | E30: 87 | F30: =E30*D30 -> 87
A31: 男维200粒 | B31: 男维200粒 | C31: 男维200粒 | D31: 1 | E31: 65 | F31: =E31*D31 -> 65
A32: 紫钙120粒两瓶装 | B32: 紫钙120粒两瓶装 | C32: 紫钙120粒两瓶装 | D32: 1 | E32: 76 | F32: =E32*D32 -> 76
A33: 紫钙120粒 | B33: 紫钙120粒 | C33: 紫钙120粒 | D33: 1 | E33: 38 | F33: =E33*D33 -> 38
A34: QWH8711000342107YWXCC | B34: QWH8711000342107YWXCC | C34: =VLOOKUP(B34,成本表!A:B,2,FALSE) -> 摩可纳10号 | D34: 1 | E34: 107 | F34: =E34*D34 -> 107
A35: QWH8711000075333YWXCC | B35: QWH8711000075333YWXCC | C35: =VLOOKUP(B35,成本表!A:B,2,FALSE) -> 摩卡纳8号 | D35: 1 | E35: 107 | F35: =E35*D35 -> 107
A36: QWH9313923031817YWXCC | B36: QWH9313923031817YWXCC | C36: =VLOOKUP(B36,成本表!A:B,2,FALSE) -> 和丽康海藻钙 | D36: 1 | E36: =VLOOKUP(B36,成本表!A:C,3,FALSE) -> 76 | F36: =E36*D36 -> 76
A37: QWH9313923031817YWXCC-3 | B37: QWH9313923031817YWXCC | C37: =VLOOKUP(B37,成本表!A:B,2,FALSE) -> 和丽康海藻钙 | D37: 3 | E37: =VLOOKUP(B37,成本表!A:C,3,FALSE) -> 76 | F37: =E37*D37 -> 228
A38: 粉钙200粒两瓶装 | B38: 粉钙200粒两瓶装 | C38: 粉钙200粒两瓶装 | D38: 1 | E38: 100 | F38: =E38*D38 -> 100
A39: 粉钙200粒 | B39: 粉钙200粒 | C39: 粉钙200粒 | D39: 1 | E39: 50 | F39: =E39*D39 -> 50
A40: 粉钙120粒 | B40: 粉钙120粒 | C40: 粉钙120粒 | D40: 1 | E40: 38 | F40: =E40*D40 -> 38
A41: QWH9415007005469YWXC | B41: QWH9415007005469YWXC | C41: =VLOOKUP(B41,成本表!A:B,2,FALSE) -> 安怡长青1700G | D41: 1 | E41: =VLOOKUP(B41,成本表!A:C,3,FALSE) -> 70 | F41: =E41*D41 -> 70
A42: QWH4560122001072YWXCC | B42: QWH4560122001072YWXCC | C42: dokan180酵素 | D42: 1 | E42: 110 | F42: =E42*D42 -> 110
A43: QWH4560122001072YWXCC-2 | B43: QWH4560122001072YWXCC | C43: dokan180酵素*2 | D43: 2 | E43: 110 | F43: =E43*D43 -> 220
A44: QWH4560122001072YWXCC-3 | B44: QWH4560122001072YWXCC | C44: dokan180酵素*3 | D44: 3 | E44: 110 | F44: =E44*D44 -> 330
A45: QWH4560122001072YWXCC-6 | B45: QWH4560122001072YWXCC | C45: dokan180酵素*6 | D45: 6 | E45: 110 | F45: =E45*D45 -> 660
A46: QWH4891035065913YWXC-6 | B46: QWH4891035065913YWXC | C46: =VLOOKUP(B46,成本表!A:B,2,FALSE) -> 雅培金装900G | D46: 6 | E46: 180 | F46: =E46*D46 -> 1080
A47: QWH4891035065913YWXCC | B47: QWH4891035065913YWXCC | C47: 雅培金装900g*1 | D47: 1 | E47: 180 | F47: =E47*D47 -> 180
A48: QWH4891035065913YWXC-4 | B48: QWH4891035065913YWXC | C48: 雅培金装900g*4 | D48: 4 | E48: 180 | F48: =E48*D48 -> 720
A49: QWH4891118018645YWXCC-2 | B49: QWH4891118018645YWXCC | C49: 雅培怡保康850G*2 | D49: 2 | E49: 187 | F49: =E49*D49 -> 374
...

Sheet 成本表
A1: 商品编码 | B1: 商品名称 | C1: 成本
A2: QWH4891035068884YWXCC | B2: 雅培怡保康礼盒850G*2 | C2: 382
A3: QWH8886451011299YWXCC | B3: 雅培怡保康850G | C3: 187
A4: RN84745786897219091815 | B4: 雅培怡保康850G | C4: 187
A5: QWH4891035069164YWXCC | B5: 雅培金装礼盒900G*2 | C5: 338
A6: QWH4891035065913YWXC | B6: 雅培金装900G | C6: 180
A7: QWH4891035065913AYWXCC | B7: 雅培金装900G | C7: 180
A8: QWH4891035065982AYWXCC | B8: 雅培低糖850G | C8: 175
A9: QWH4891035065982YWXC | B9: 雅培低糖850G | C9: 175
A10: QWH4891118025278YWXCZY | B10: 雀巢速愈素 | C10: 199
A11: QWH4891118018645YWXCC | B11: 雀巢即溶奶粉2.2KG | C11: 159
A12: QWH043900293219YWXCZY | B12: 雀巢蛋白补227 | C12: 72.5
A13: QWH8711000342107YWXCC | B13: 摩可纳10号 | C13: 103.5
... A17: QWH8445290770189YWXCZY | B17: 雀巢代餐奶昔-巧克力味 | C17: 107

Sheet 母婴奶粉编码
A1: TCWL001 | B1: TCWL001#2 | C1: TCWL001#3 | D1: TCWL001#4 | E1: TCWL001#5 | F1: TCWL001#6
A2: TCWL002 | B2: TCWL002#2 | C2: TCWL002#3 | D2: TCWL002#4 | E2: TCWL002#5 | F2: TCWL002#6
A3: TCWL003 | B3: TCWL003#2 | C3: TCWL003#3 | D3: TCWL003#4 | E3: TCWL003#5 | F3: TCWL003#6
A4: TCWL004 | B4: TCWL004#2 | C4: TCWL004#3 | D4: TCWL004#4 | E4: TCWL004#5 | F4: TCWL004#6
A5: TCJZ001 | B5: TCJZ001#2 | C5: TCJZ001#3 | D5: TCJZ001#4 | E5: TCJZ001#5 | F5: TCJZ001#6
A6: TCJZ002 | B6: TCJZ002#2 | C6: TCJZ002#3 | D6: TCJZ002#4 | E6: TCJZ002#5 | F6: TCJZ002#6
A7: TCJZ003 | B7: TCJZ003#2 | C7: TCJZ003#3 | D7: TCJZ003#4 | E7: TCJZ003#5 | F7: TCJZ003#6
A8: TCJZ004 | B8: TCJZ004#2 | C8: TCJZ004#3 | D8: TCJZ004#4 | E8: TCJZ004#5 | F8: TCJZ004#6
A9: TCZYG002 | B9: TCZYG002#2 | C9: TCZYG002#3 | D9: TCZYG002#4 | E9: TCZYG002#5 | F9: TCZYG002#6
A10: TCZYG001 | B10: TCZYG001#2 | C10: TCZYG001#3 | D10: TCZYG001#4 | E10: TCZYG001#5 | F10: TCZYG001#6
A11: TCHSA21 | B11: TCHSA21#2 | C11: TCHSA21#3 | D11: TCHSA21#4 | E11: TCHSA21#5 | F11: TCHSA21#6
A12: TCHSA23 | B12: TCHSA23#2 | C12: TCHSA23#3 | D12: TCHSA23#4 | E12: TCHSA23#5 | F12: TCHSA23#6
... A25: TCQCQH004 | B25: TCQCQH004#2 | C25: TCQCQH004#3 | D25: TCQCQH004#4 | E25: TCQCQH004#5 | F25: TCQCQH004#6
